âœ“ WandB initialized in Online mode
[34m[1mwandb[0m: 500 encountered ({"errors":[{"message":"An internal error occurred. Please contact support.","path":["upsertBucket"]}],"data":{"upsertBucket":null}}), retrying request
Traceback (most recent call last):
  File "/home/ajinkya/projects/TestRepo_MsThesis_Ajinkya/week8/main.py", line 446, in <module>
    main()
  File "/home/ajinkya/projects/TestRepo_MsThesis_Ajinkya/week8/main.py", line 381, in main
    trainloader, testloader = train_test_loader(config.datasetpath,config.illusion_dataset_bool)
                                                                   ^^^^^^^^^^^^^^^^^^^^^^^^^^^^
AttributeError: module 'config14' has no attribute 'illusion_dataset_bool'
