âœ“ WandB initialized in Online mode
Files already downloaded and verified
Files already downloaded and verified
The Iteration0:
================================
Epoch:0 and AverageLoss:0.199254278693815
Test Loss 0.09312840268204484
Epoch:1 and AverageLoss:0.07624095974637725
Test Loss 0.06388386244638057
Epoch:2 and AverageLoss:0.056828545449334945
Test Loss 0.050773772352103945
Epoch:3 and AverageLoss:0.04671911237870946
Test Loss 0.04300051776668693
Epoch:4 and AverageLoss:0.04034101179874767
Test Loss 0.03778446772241894
Epoch:5 and AverageLoss:0.03589085514283241
Test Loss 0.03400795355061941
Epoch:6 and AverageLoss:0.032585124592380145
Test Loss 0.03112068529464776
Epoch:7 and AverageLoss:0.030000350330872914
Test Loss 0.02882364816680739
Epoch:8 and AverageLoss:0.027915641022345904
Test Loss 0.02693889431561096
Epoch:9 and AverageLoss:0.026187570379746845
Test Loss 0.025357394632470758
Model Save Sucessfully
Training Sucessful
The Iteration1:
================================
Epoch:0 and AverageLoss:0.0247498643453545
Test Loss 0.024033535531238666
Epoch:1 and AverageLoss:0.023486144678748173
Test Loss 0.022855716415598422
Epoch:2 and AverageLoss:0.02238018810749054
Test Loss 0.021820510112786594
Epoch:3 and AverageLoss:0.021403828659630798
Test Loss 0.02090225123529193
Epoch:4 and AverageLoss:0.020533321839769175
Test Loss 0.020080918658383285
Epoch:5 and AverageLoss:0.019751766806139666
Test Loss 0.019339413747568673
Error in sys.excepthook:
Traceback (most recent call last):
  File "/home/ajinkya/miniconda3/envs/cuda_pyt/lib/python3.12/site-packages/wandb/sdk/lib/exit_hooks.py", line 52, in exc_handler
    traceback.print_exception(exc_type, exc, tb)
  File "/home/ajinkya/miniconda3/envs/cuda_pyt/lib/python3.12/traceback.py", line 124, in print_exception
    te = TracebackException(type(value), value, tb, limit=limit, compact=True)
         ^^^^^^^^^^^^^^^^^^^^^^^^^^^^^^^^^^^^^^^^^^^^^^^^^^^^^^^^^^^^^^^^^^^^^
  File "/home/ajinkya/miniconda3/envs/cuda_pyt/lib/python3.12/traceback.py", line 733, in __init__
    self.stack = StackSummary._extract_from_extended_frame_gen(
                 ^^^^^^^^^^^^^^^^^^^^^^^^^^^^^^^^^^^^^^^^^^^^^^
  File "/home/ajinkya/miniconda3/envs/cuda_pyt/lib/python3.12/traceback.py", line 438, in _extract_from_extended_frame_gen
    f.line
  File "/home/ajinkya/miniconda3/envs/cuda_pyt/lib/python3.12/traceback.py", line 323, in line
    self._line = linecache.getline(self.filename, self.lineno)
                 ^^^^^^^^^^^^^^^^^^^^^^^^^^^^^^^^^^^^^^^^^^^^^
  File "/home/ajinkya/miniconda3/envs/cuda_pyt/lib/python3.12/linecache.py", line 30, in getline
    lines = getlines(filename, module_globals)
            ^^^^^^^^^^^^^^^^^^^^^^^^^^^^^^^^^^
  File "/home/ajinkya/miniconda3/envs/cuda_pyt/lib/python3.12/linecache.py", line 46, in getlines
    return updatecache(filename, module_globals)
           ^^^^^^^^^^^^^^^^^^^^^^^^^^^^^^^^^^^^^
  File "/home/ajinkya/miniconda3/envs/cuda_pyt/lib/python3.12/linecache.py", line 141, in updatecache
    with tokenize.open(fullname) as fp:
         ^^^^^^^^^^^^^^^^^^^^^^^
  File "/home/ajinkya/miniconda3/envs/cuda_pyt/lib/python3.12/tokenize.py", line 459, in open
    encoding, lines = detect_encoding(buffer.readline)
                      ^^^^^^^^^^^^^^^^^^^^^^^^^^^^^^^^
  File "/home/ajinkya/miniconda3/envs/cuda_pyt/lib/python3.12/tokenize.py", line 428, in detect_encoding
    first = read_or_stop()
            ^^^^^^^^^^^^^^
  File "/home/ajinkya/miniconda3/envs/cuda_pyt/lib/python3.12/tokenize.py", line 386, in read_or_stop
    return readline()
           ^^^^^^^^^^
KeyboardInterrupt

Original exception was:
Traceback (most recent call last):
  File "/home/ajinkya/projects/TestRepo_MsThesis_Ajinkya/week7/zp_study/main.py", line 225, in <module>
    main()
  File "/home/ajinkya/projects/TestRepo_MsThesis_Ajinkya/week7/zp_study/main.py", line 187, in main
