âœ“ WandB initialized in Online mode
Files already downloaded and verified
Files already downloaded and verified
The Iteration0:
================================
Traceback (most recent call last):
  File "/home/ajinkya/projects/TestRepo_MsThesis_Ajinkya/week8/main.py", line 230, in <module>
    main()
  File "/home/ajinkya/projects/TestRepo_MsThesis_Ajinkya/week8/main.py", line 198, in main
    train_bool = training_using_illusions(net,save_dir,illusion_trainloader,illusion_testloader,config)
                 ^^^^^^^^^^^^^^^^^^^^^^^^^^^^^^^^^^^^^^^^^^^^^^^^^^^^^^^^^^^^^^^^^^^^^^^^^^^^^^^^^^^^^^
  File "/home/ajinkya/projects/TestRepo_MsThesis_Ajinkya/week8/main.py", line 139, in training_using_illusions
    for batch_idx,batch in enumerate(illusion_trainloader):
                           ^^^^^^^^^^^^^^^^^^^^^^^^^^^^^^^
  File "/home/ajinkya/miniconda3/envs/cuda_pyt/lib/python3.12/site-packages/torch/utils/data/dataloader.py", line 701, in __next__
    data = self._next_data()
           ^^^^^^^^^^^^^^^^^
  File "/home/ajinkya/miniconda3/envs/cuda_pyt/lib/python3.12/site-packages/torch/utils/data/dataloader.py", line 1465, in _next_data
    return self._process_data(data)
           ^^^^^^^^^^^^^^^^^^^^^^^^
  File "/home/ajinkya/miniconda3/envs/cuda_pyt/lib/python3.12/site-packages/torch/utils/data/dataloader.py", line 1491, in _process_data
    data.reraise()
  File "/home/ajinkya/miniconda3/envs/cuda_pyt/lib/python3.12/site-packages/torch/_utils.py", line 715, in reraise
    raise exception
FileNotFoundError: Caught FileNotFoundError in DataLoader worker process 0.
Original Traceback (most recent call last):
  File "/home/ajinkya/miniconda3/envs/cuda_pyt/lib/python3.12/site-packages/torch/utils/data/_utils/worker.py", line 351, in _worker_loop
    data = fetcher.fetch(index)  # type: ignore[possibly-undefined]
           ^^^^^^^^^^^^^^^^^^^^
  File "/home/ajinkya/miniconda3/envs/cuda_pyt/lib/python3.12/site-packages/torch/utils/data/_utils/fetch.py", line 52, in fetch
    data = [self.dataset[idx] for idx in possibly_batched_index]
            ~~~~~~~~~~~~^^^^^
  File "/home/ajinkya/projects/TestRepo_MsThesis_Ajinkya/week8/custom_dataset.py", line 17, in __getitem__
    img = Image.open(fn).convert('RGB')
      ^^^^^^^^^^^^^^
  File "/home/ajinkya/miniconda3/envs/cuda_pyt/lib/python3.12/site-packages/PIL/Image.py", line 3465, in open
    fp = builtins.open(filename, "rb")
         ^^^^^^^^^^^^^^^^^^^^^^^^^^^^^
FileNotFoundError: [Errno 2] No such file or directory: 'data/illusory0.1/test/2/2_AllOut_304.png'
