Traceback (most recent call last):
  File "/home/ajinkyar/miniconda3/envs/cuda_pyt/lib/python3.12/site-packages/wandb/sdk/wandb_config.py", line 165, in __getattr__
    return self.__getitem__(key)
           ^^^^^^^^^^^^^^^^^^^^^
  File "/home/ajinkyar/miniconda3/envs/cuda_pyt/lib/python3.12/site-packages/wandb/sdk/wandb_config.py", line 130, in __getitem__
    return self._items[key]
           ~~~~~~~~~~~^^^^^
KeyError: 'batch_size'

The above exception was the direct cause of the following exception:

Traceback (most recent call last):
  File "/home/ajinkyar/projects/TestRepo_MsThesis_Ajinkya/week3/main.py", line 220, in <module>
    batch_size=config.batch_size
               ^^^^^^^^^^^^^^^^^
  File "/home/ajinkyar/miniconda3/envs/cuda_pyt/lib/python3.12/site-packages/wandb/sdk/wandb_config.py", line 167, in __getattr__
    raise AttributeError(
AttributeError: <class 'wandb.sdk.wandb_config.Config'> object has no attribute 'batch_size'
